Workbook

Sheet Sheet1
A3: AUTOCAL SOLUTIONS PVT. LTD.
A4: Laboratory: 06, Gurusampada Society, Vanvihar Colony,
A5: Behind Bhonsala School, Nashik - 422 005, Maharashtra, India.
A6: Email Id: nashiklab@autocal.net Web Adderess: www.autocal.net
A7: Phone No.: (0253) 2352168
N8: Cert. No.: C-1505
E11: CALIBRATION CERTIFICATE | N11: 5.10/R/E-01,Rev. 01
N12: Page 1 of 2
A13: Certificate No. | D13: 16174766/N/ET/01 | H13: Issue Date | M13: 17/02/2017
A14: Date of Calibration | D14: 16/02/2017 | H14: Recommended Next Calibration Date | M14: 15/02/2018
A16: Service Request Form No. | F16: 16174766
A17: Calibrated for | F17: M/s.Enam Casting Pvt Ltd
F18: D-72,MIDC Area, Satpur,Nashik - 422 007.
A20: Date of Receipt of Instrument | F20: =D14 -> 16/02/2017
A21: Condition of Instrument on Receipt | F21: Working | I21: Calibrated at | M21: Site
A22: Details of Unit Under Calibration (UUC) :
A23: Description | D23: Analog H.V. Tester (AC) | H23: Range | L23: 0 to 100 kV AC @ 50Hz
A24: Make / Model | D24: Ericon Transformer | H24: Resolution | L24: 2 kV AC
A25: Serial No. | D25: HVT-726 | H25: Accuracy | L25: ±5% Fsd
A26: ID No. | D26: --- | H26: Work Instruction No. | L26: WI/ASPL/CAL/ET-06 &19
A27: Environmental Conditions :
A28: Temperature | E28: 25 ±5°C | I28: Relative Humidity | M28: 60 ±15%RH
A30: Details of Standard Used for Calibration (Traceable to National / International Standards)
A31: Description | D31: Make / Model | G31: Serial No. | J31: Traceability ( Certificate No. ) | N31: Valid Upto
A32: H.V. Divider with kV meter | D32: Wavetek / 9100 | G32: STD/NSK/ET-01 | J32: ASPL, Vasai | N32: 23/02/2017
J33: ( 15164490/ET/11 )
A35: Measurement Result Refer to Page No. 2
A37: Remarks
A38: 1. The reported expanded uncertainty of measurement is stated as a standard uncertainty of measurement multiplied by coverage factor 'k' such that the coverage probabilty corresponds to approximately 95.45% confidence level.
A39: 2. The measured values mentioned are the average of 5 readings.
A40: 3. Measured readings have been mentioned.
A41: 4. Readings taken as per customer request.
A42: Notes
A43: 1. This report refers only to particular item calibrated at site/ Laboratory.
A44: 2. The calibration results reported are valid at the time of and under the stated conditions of measurement.
A45: 3. Any correction in this certificate invalidates this certificate.
A46: 4. This certificate shall not be reproduced except, in full without the written approval from the Laboratory.
A56: Calibrated By | L56: Authorised Signatory
A57: Bhupendra Ozarkar | L57: Baviskar P.U.
A58: Calibration Engineer | L58: Technical Manager
...

Sheet Sheet2
B2: Certificate No. | E2: =Sheet1!D13 -> 16174766/N/ET/01 | I2: Issue Date | N2: =Sheet1!M13 -> 17/02/2017
B3: Date of Calibration | E3: =Sheet1!D14 -> 16/02/2017 | I3: Recommended Next Calibration Date | N3: =Sheet1!M14 -> 15/02/2018
B5: Service Request Form No. | G5: =Sheet1!F16 -> 16174766
B6: Calibrated for | G6: =Sheet1!F17 -> M/s.Enam Casting Pvt Ltd
G7: =Sheet1!F18 -> D-72,MIDC Area, Satpur,Nashik - 422 007.
B12: UNCERTAINTY EVALUATION
B14: =Sheet1!D23 -> Analog H.V. Tester (AC)
B15: =Sheet1!A13 -> Certificate No. | D15: =Sheet1!D13 -> 16174766/N/ET/01
A16: Test Point | B16: Type "A" (Repeatability) | G16: Avg. | H16: SD | I16: Ua | J16: Limits (%) | K16: Divisor | L16: Ub1 | M16: Limits (%) | N16: Divisor | O16: Ub2 | Q16: Limits (A) | R16: Divisor | S16: Ub3 (%) | T16: Uc (%) | U16: DOF | V16: k | W16: Ux (%) | Y16: CMC as per Scope (%rdg) | Z16: Final Un.
A17: =Sheet1!O78 -> 0 | B17: 0 | C17: 0 | D17: 0 | E17: 0 | F17: 0 | G17: =AVERAGE(B17:F17) -> 0 | H17: =STDEV(B17:F17) -> 0 | I17: =H17/SQRT(5)*100/A17 -> #DIV/0! | J17: 0.026 | K17: 2 | L17: =J17/K17 -> 0.013 | M17: 2 | N17: 1.732 | O17: =(M17/N17) -> 1.1547344 | Q17: 2 | R17: 1.732 | S17: =(Q17/2)/R17*100/A17 -> #DIV/0! | T17: =SQRT(I17*I17+L17*L17+O17*O17+S17*S17) -> #DIV/0! | U17: =(T17*T17*T17*T17)/((I17*I17*I17*I17)/4) -> #DIV/0! | V17: =IF(U17="Infinity",2,IF(U17<30,CHOOSE(U17,13.97,4.53,3.31,2.87,2.65,2.52,2.43,2.37,2.32,2.28,2.25,2.23,2.21,2.2,2.18,2.17,2.16,2.15,2.14,2.13,2.13,2.12,2.12,2.11,2.11,2.1,2.1,2.09,2.09),2)) -> #DIV/0! | W17: =ABS(T17*V17) -> #DIV/0! | Y17: 0.17 | Z17: =MAX(W17:Y17) -> #DIV/0!
A18: =Sheet1!O79 -> 10 | B18: 10.8 | C18: 10.8 | D18: 10.8 | E18: 10.81 | F18: 10.8 | G18: =AVERAGE(B18:F18) -> 10.802 | H18: =STDEV(B18:F18) -> 0.004472136 | I18: =H18/SQRT(5)*100/A18 -> 0.02 | J18: 0.026 | K18: 2 | L18: =J18/K18 -> 0.013 | M18: 2 | N18: 1.732 | O18: =(M18/N18) -> 1.1547344 | Q18: 2 | R18: 1.732 | S18: =(Q18/2)/R18*100/100 -> 0.57736721 | T18: =SQRT(I18*I18+L18*L18+O18*O18+S18*S18) -> 1.2912527 | U18: =(T18*T18*T18*T18)/((I18*I18*I18*I18)/4) -> 69500021 | V18: =IF(U18="Infinity",2,IF(U18<30,CHOOSE(U18,13.97,4.53,3.31,2.87,2.65,2.52,2.43,2.37,2.32,2.28,2.25,2.23,2.21,2.2,2.18,2.17,2.16,2.15,2.14,2.13,2.13,2.12,2.12,2.11,2.11,2.1,2.1,2.09,2.09),2)) -> 2 | W18: =ABS(T18*V18) -> 2.5825053 | Y18: 3 | Z18: =MAX(W18:Y18) -> 3
A19: =Sheet1!O80 -> 20 | B19: 21.89 | C19: 21.89 | D19: 21.89 | E19: 21.87 | F19: 21.89 | G19: =AVERAGE(B19:F19) -> 21.886 | H19: =STDEV(B19:F19) -> 0.0089442719 | I19: =H19/SQRT(5)*100/A19 -> 0.02 | J19: 0.026 | K19: 2 | L19: =J19/K19 -> 0.013 | M19: 2 | N19: 1.732 | O19: =(M19/N19) -> 1.1547344 | Q19: 2 | R19: 1.732 | S19: =(Q19/2)/R19*100/100 -> 0.57736721 | T19: =SQRT(I19*I19+L19*L19+O19*O19+S19*S19) -> 1.2912527 | U19: =(T19*T19*T19*T19)/((I19*I19*I19*I19)/4) -> 69500021 | V19: =IF(U19="Infinity",2,IF(U19<30,CHOOSE(U19,13.97,4.53,3.31,2.87,2.65,2.52,2.43,2.37,2.32,2.28,2.25,2.23,2.21,2.2,2.18,2.17,2.16,2.15,2.14,2.13,2.13,2.12,2.12,2.11,2.11,2.1,2.1,2.09,2.09),2)) -> 2 | W19: =ABS(T19*V19) -> 2.5825053 | Y19: 3 | Z19: =MAX(W19:Y19) -> 3
A20: =Sheet1!O81 -> 30 | B20: 32.94 | C20: 32.94 | D20: 32.94 | E20: 32.95 | F20: 32.94 | G20: =AVERAGE(B20:F20) -> 32.942 | H20: =STDEV(B20:F20) -> 0.004472136 | I20: =H20/SQRT(5)*100/A20 -> 0.0066666667 | J20: 0.026 | K20: 2 | L20: =J20/K20 -> 0.013 | M20: 2 | N20: 1.732 | O20: =(M20/N20) -> 1.1547344 | Q20: 2 | R20: 1.732 | S20: =(Q20/2)/R20*100/100 -> 0.57736721 | T20: =SQRT(I20*I20+L20*L20+O20*O20+S20*S20) -> 1.291115 | U20: =(T20*T20*T20*T20)/((I20*I20*I20*I20)/4) -> 5.627101e+09 | V20: =IF(U20="Infinity",2,IF(U20<30,CHOOSE(U20,13.97,4.53,3.31,2.87,2.65,2.52,2.43,2.37,2.32,2.28,2.25,2.23,2.21,2.2,2.18,2.17,2.16,2.15,2.14,2.13,2.13,2.12,2.12,2.11,2.11,2.1,2.1,2.09,2.09),2)) -> 2 | W20: =ABS(T20*V20) -> 2.58223 | Y20: 3 | Z20: =MAX(W20:Y20) -> 3
A21: =Sheet1!O82 -> 40 | B21: 43.72 | C21: 43.72 | D21: 43.72 | E21: 43.73 | F21: 43.72 | G21: =AVERAGE(B21:F21) -> 43.722 | H21: =STDEV(B21:F21) -> 0.004472136 | I21: =H21/SQRT(5)*100/A21 -> 0.005 | J21: 0.026 | K21: 2 | L21: =J21/K21 -> 0.013 | M21: 2 | N21: 1.732 | O21: =(M21/N21) -> 1.1547344 | Q21: 2 | R21: 1.732 | S21: =(Q21/2)/R21*100/100 -> 0.57736721 | T21: =SQRT(I21*I21+L21*L21+O21*O21+S21*S21) -> 1.2911075 | U21: =(T21*T21*T21*T21)/((I21*I21*I21*I21)/4) -> 1.7784003e+10 | V21: =IF(U21="Infinity",2,IF(U21<30,CHOOSE(U21,13.97,4.53,3.31,2.87,2.65,2.52,2.43,2.37,2.32,2.28,2.25,2.23,2.21,2.2,2.18,2.17,2.16,2.15,2.14,2.13,2.13,2.12,2.12,2.11,2.11,2.1,2.1,2.09,2.09),2)) -> 2 | W21: =ABS(T21*V21) -> 2.5822149 | Y21: 3 | Z21: =MAX(W21:Y21) -> 3
A22: =Sheet1!O83 -> 50 | B22: 54.17 | C22: 54.17 | D22: 54.17 | E22: 54.18 | F22: 54.17 | G22: =AVERAGE(B22:F22) -> 54.172 | H22: =STDEV(B22:F22) -> 0.004472136 | I22: =H22/SQRT(5)*100/A22 -> 0.004 | J22: 0.026 | K22: 2 | L22: =J22/K22 -> 0.013 | M22: 2 | N22: 1.732 | O22: =(M22/N22) -> 1.1547344 | Q22: 2 | R22: 1.732 | S22: =(Q22/2)/R22*100/100 -> 0.57736721 | T22: =SQRT(I22*I22+L22*L22+O22*O22+S22*S22) -> 1.291104 | U22: =(T22*T22*T22*T22)/((I22*I22*I22*I22)/4) -> 4.3417507e+10 | V22: =IF(U22="Infinity",2,IF(U22<30,CHOOSE(U22,13.97,4.53,3.31,2.87,2.65,2.52,2.43,2.37,2.32,2.28,2.25,2.23,2.21,2.2,2.18,2.17,2.16,2.15,2.14,2.13,2.13,2.12,2.12,2.11,2.11,2.1,2.1,2.09,2.09),2)) -> 2 | W22: =ABS(T22*V22) -> 2.5822079 | Y22: 3 | Z22: =MAX(W22:Y22) -> 3
A23: =Sheet1!O84 -> 60 | B23: 64.42 | C23: 64.42 | D23: 64.42 | E23: 64.43 | F23: 64.42 | G23: =AVERAGE(B23:F23) -> 64.422 | H23: =STDEV(B23:F23) -> 0.004472136 | I23: =H23/SQRT(5)*100/A23 -> 0.0033333333 | J23: 0.026 | K23: 2 | L23: =J23/K23 -> 0.013 | M23: 2 | N23: 1.732 | O23: =(M23/N23) -> 1.1547344 | Q23: 2 | R23: 1.732 | S23: =(Q23/2)/R23*100/100 -> 0.57736721 | T23: =SQRT(I23*I23+L23*L23+O23*O23+S23*S23) -> 1.2911021 | U23: =(T23*T23*T23*T23)/((I23*I23*I23*I23)/4) -> 9.0030015e+10 | V23: =IF(U23="Infinity",2,IF(U23<30,CHOOSE(U23,13.97,4.53,3.31,2.87,2.65,2.52,2.43,2.37,2.32,2.28,2.25,2.23,2.21,2.2,2.18,2.17,2.16,2.15,2.14,2.13,2.13,2.12,2.12,2.11,2.11,2.1,2.1,2.09,2.09),2)) -> 2 | W23: =ABS(T23*V23) -> 2.5822041 | Y23: 3 | Z23: =MAX(W23:Y23) -> 3
A24: =Sheet1!O85 -> 70 | B24: 74.61 | C24: 74.61 | D24: 74.61 | E24: 74.62 | F24: 74.61 | G24: =AVERAGE(B24:F24) -> 74.612 | H24: =STDEV(B24:F24) -> 0.004472136 | I24: =H24/SQRT(5)*100/A24 -> 0.0028571429 | J24: 0.026 | K24: 2 | L24: =J24/K24 -> 0.013 | M24: 2 | N24: 1.732 | O24: =(M24/N24) -> 1.1547344 | Q24: 2 | R24: 1.732 | S24: =(Q24/2)/R24*100/100 -> 0.57736721 | T24: =SQRT(I24*I24+L24*L24+O24*O24+S24*S24) -> 1.2911009 | U24: =(T24*T24*T24*T24)/((I24*I24*I24*I24)/4) -> 1.6679113e+11 | V24: =IF(U24="Infinity",2,IF(U24<30,CHOOSE(U24,13.97,4.53,3.31,2.87,2.65,2.52,2.43,2.37,2.32,2.28,2.25,2.23,2.21,2.2,2.18,2.17,2.16,2.15,2.14,2.13,2.13,2.12,2.12,2.11,2.11,2.1,2.1,2.09,2.09),2)) -> 2 | W24: =ABS(T24*V24) -> 2.5822019 | Y24: 3 | Z24: =MAX(W24:Y24) -> 3
